[2025-05-27T05:22:41.247+0000] {taskinstance.py:1159} INFO - Dependencies all met for dep_context=non-requeueable deps ti=<TaskInstance: walmart_etl_dag.load_to_ods manual__2025-05-27T05:15:27+00:00 [queued]>
[2025-05-27T05:22:41.267+0000] {taskinstance.py:1159} INFO - Dependencies all met for dep_context=requeueable deps ti=<TaskInstance: walmart_etl_dag.load_to_ods manual__2025-05-27T05:15:27+00:00 [queued]>
[2025-05-27T05:22:41.269+0000] {taskinstance.py:1361} INFO - Starting attempt 1 of 2
[2025-05-27T05:22:41.296+0000] {taskinstance.py:1382} INFO - Executing <Task(PythonOperator): load_to_ods> on 2025-05-27 05:15:27+00:00
[2025-05-27T05:22:41.316+0000] {standard_task_runner.py:57} INFO - Started process 208 to run task
[2025-05-27T05:22:41.322+0000] {standard_task_runner.py:84} INFO - Running: ['***', 'tasks', 'run', 'walmart_etl_dag', 'load_to_ods', 'manual__2025-05-27T05:15:27+00:00', '--job-id', '29', '--raw', '--subdir', 'DAGS_FOLDER/walmart_etl_dag.py', '--cfg-path', '/tmp/tmpqt7xj3l1']
[2025-05-27T05:22:41.324+0000] {standard_task_runner.py:85} INFO - Job 29: Subtask load_to_ods
[2025-05-27T05:22:41.379+0000] {task_command.py:416} INFO - Running <TaskInstance: walmart_etl_dag.load_to_ods manual__2025-05-27T05:15:27+00:00 [running]> on host 364c8c3dd6ab
[2025-05-27T05:22:41.435+0000] {taskinstance.py:1662} INFO - Exporting env vars: AIRFLOW_CTX_DAG_OWNER='***' AIRFLOW_CTX_DAG_ID='walmart_etl_dag' AIRFLOW_CTX_TASK_ID='load_to_ods' AIRFLOW_CTX_EXECUTION_DATE='2025-05-27T05:15:27+00:00' AIRFLOW_CTX_TRY_NUMBER='1' AIRFLOW_CTX_DAG_RUN_ID='manual__2025-05-27T05:15:27+00:00'
[2025-05-27T05:22:41.492+0000] {logging_mixin.py:154} INFO - Loaded 8399 rows from CSV file.
[2025-05-27T05:22:41.860+0000] {taskinstance.py:1937} ERROR - Task failed with exception
Traceback (most recent call last):
  File "/home/airflow/.local/lib/python3.8/site-packages/airflow/operators/python.py", line 192, in execute
    return_value = self.execute_callable()
  File "/home/airflow/.local/lib/python3.8/site-packages/airflow/operators/python.py", line 209, in execute_callable
    return self.python_callable(*self.op_args, **self.op_kwargs)
  File "/opt/airflow/dags/walmart_etl_dag.py", line 84, in etl_load_to_ods
    load_ods_layer(engine, df)
  File "/opt/airflow/walmart-etl/etl_data_loader.py", line 338, in load_ods_layer
    load_ods_date_dimension(engine, df)
  File "/opt/airflow/walmart-etl/etl_data_loader.py", line 110, in load_ods_date_dimension
    conn.commit()
AttributeError: 'Connection' object has no attribute 'commit'
[2025-05-27T05:22:41.876+0000] {taskinstance.py:1400} INFO - Marking task as UP_FOR_RETRY. dag_id=walmart_etl_dag, task_id=load_to_ods, execution_date=20250527T051527, start_date=20250527T052241, end_date=20250527T052241
[2025-05-27T05:22:41.891+0000] {standard_task_runner.py:104} ERROR - Failed to execute job 29 for task load_to_ods ('Connection' object has no attribute 'commit'; 208)
[2025-05-27T05:22:41.918+0000] {local_task_job_runner.py:228} INFO - Task exited with return code 1
[2025-05-27T05:22:41.942+0000] {taskinstance.py:2778} INFO - 0 downstream tasks scheduled from follow-on schedule check
