[2025-05-27T22:23:46.125+0000] {taskinstance.py:1159} INFO - Dependencies all met for dep_context=non-requeueable deps ti=<TaskInstance: inventory_returns_generation.generate_inventory_data manual__2025-05-27T22:23:43.610913+00:00 [queued]>
[2025-05-27T22:23:46.131+0000] {taskinstance.py:1159} INFO - Dependencies all met for dep_context=requeueable deps ti=<TaskInstance: inventory_returns_generation.generate_inventory_data manual__2025-05-27T22:23:43.610913+00:00 [queued]>
[2025-05-27T22:23:46.132+0000] {taskinstance.py:1361} INFO - Starting attempt 1 of 2
[2025-05-27T22:23:46.140+0000] {taskinstance.py:1382} INFO - Executing <Task(PythonOperator): generate_inventory_data> on 2025-05-27 22:23:43.610913+00:00
[2025-05-27T22:23:46.155+0000] {standard_task_runner.py:57} INFO - Started process 171 to run task
[2025-05-27T22:23:46.158+0000] {standard_task_runner.py:84} INFO - Running: ['***', 'tasks', 'run', 'inventory_returns_generation', 'generate_inventory_data', 'manual__2025-05-27T22:23:43.610913+00:00', '--job-id', '478', '--raw', '--subdir', 'DAGS_FOLDER/inventory_returns_dag.py', '--cfg-path', '/tmp/tmpwz9q94_6']
[2025-05-27T22:23:46.160+0000] {standard_task_runner.py:85} INFO - Job 478: Subtask generate_inventory_data
[2025-05-27T22:23:46.188+0000] {task_command.py:416} INFO - Running <TaskInstance: inventory_returns_generation.generate_inventory_data manual__2025-05-27T22:23:43.610913+00:00 [running]> on host 096aa9233816
[2025-05-27T22:23:46.367+0000] {taskinstance.py:1662} INFO - Exporting env vars: AIRFLOW_CTX_DAG_OWNER='***' AIRFLOW_CTX_DAG_ID='inventory_returns_generation' AIRFLOW_CTX_TASK_ID='generate_inventory_data' AIRFLOW_CTX_EXECUTION_DATE='2025-05-27T22:23:43.610913+00:00' AIRFLOW_CTX_TRY_NUMBER='1' AIRFLOW_CTX_DAG_RUN_ID='manual__2025-05-27T22:23:43.610913+00:00'
[2025-05-27T22:23:46.400+0000] {logging_mixin.py:154} INFO - Generating inventory data...
[2025-05-27T22:23:46.405+0000] {taskinstance.py:1937} ERROR - Task failed with exception
Traceback (most recent call last):
  File "/home/airflow/.local/lib/python3.8/site-packages/airflow/operators/python.py", line 192, in execute
    return_value = self.execute_callable()
  File "/home/airflow/.local/lib/python3.8/site-packages/airflow/operators/python.py", line 209, in execute_callable
    return self.python_callable(*self.op_args, **self.op_kwargs)
  File "/opt/airflow/dags/inventory_returns_dag.py", line 67, in generate_inventory_wrapper
    return generate_inventory_data(existing_data, num_records=500)
  File "/opt/airflow/walmart-etl/generate_inventory_returns_data.py", line 120, in generate_inventory_data
    inventory_id = f"INV{uuid.uuid4().hex[:12]}"
NameError: name 'uuid' is not defined
[2025-05-27T22:23:46.410+0000] {taskinstance.py:1400} INFO - Marking task as UP_FOR_RETRY. dag_id=inventory_returns_generation, task_id=generate_inventory_data, execution_date=20250527T222343, start_date=20250527T222346, end_date=20250527T222346
[2025-05-27T22:23:46.415+0000] {standard_task_runner.py:104} ERROR - Failed to execute job 478 for task generate_inventory_data (name 'uuid' is not defined; 171)
[2025-05-27T22:23:46.460+0000] {local_task_job_runner.py:228} INFO - Task exited with return code 1
[2025-05-27T22:23:46.489+0000] {taskinstance.py:2778} INFO - 0 downstream tasks scheduled from follow-on schedule check
