[2025-05-27T05:17:57.843+0000] {taskinstance.py:1159} INFO - Dependencies all met for dep_context=non-requeueable deps ti=<TaskInstance: walmart_etl_dag.generate_synthetic_data manual__2025-05-27T05:17:47+00:00 [queued]>
[2025-05-27T05:17:57.860+0000] {taskinstance.py:1159} INFO - Dependencies all met for dep_context=requeueable deps ti=<TaskInstance: walmart_etl_dag.generate_synthetic_data manual__2025-05-27T05:17:47+00:00 [queued]>
[2025-05-27T05:17:57.861+0000] {taskinstance.py:1361} INFO - Starting attempt 1 of 2
[2025-05-27T05:17:57.873+0000] {taskinstance.py:1382} INFO - Executing <Task(PythonOperator): generate_synthetic_data> on 2025-05-27 05:17:47+00:00
[2025-05-27T05:17:57.882+0000] {standard_task_runner.py:57} INFO - Started process 89 to run task
[2025-05-27T05:17:57.892+0000] {standard_task_runner.py:84} INFO - Running: ['***', 'tasks', 'run', 'walmart_etl_dag', 'generate_synthetic_data', 'manual__2025-05-27T05:17:47+00:00', '--job-id', '25', '--raw', '--subdir', 'DAGS_FOLDER/walmart_etl_dag.py', '--cfg-path', '/tmp/tmpyfwab13k']
[2025-05-27T05:17:57.895+0000] {standard_task_runner.py:85} INFO - Job 25: Subtask generate_synthetic_data
[2025-05-27T05:17:57.960+0000] {task_command.py:416} INFO - Running <TaskInstance: walmart_etl_dag.generate_synthetic_data manual__2025-05-27T05:17:47+00:00 [running]> on host 364c8c3dd6ab
[2025-05-27T05:17:58.076+0000] {taskinstance.py:1662} INFO - Exporting env vars: AIRFLOW_CTX_DAG_OWNER='***' AIRFLOW_CTX_DAG_ID='walmart_etl_dag' AIRFLOW_CTX_TASK_ID='generate_synthetic_data' AIRFLOW_CTX_EXECUTION_DATE='2025-05-27T05:17:47+00:00' AIRFLOW_CTX_TRY_NUMBER='1' AIRFLOW_CTX_DAG_RUN_ID='manual__2025-05-27T05:17:47+00:00'
[2025-05-27T05:17:58.080+0000] {logging_mixin.py:154} INFO - Starting synthetic data generation process...
[2025-05-27T05:17:58.082+0000] {logging_mixin.py:154} INFO - Generating supplier data...
[2025-05-27T05:17:58.108+0000] {taskinstance.py:1937} ERROR - Task failed with exception
Traceback (most recent call last):
  File "/home/airflow/.local/lib/python3.8/site-packages/sqlalchemy/engine/base.py", line 1910, in _execute_context
    self.dialect.do_execute(
  File "/home/airflow/.local/lib/python3.8/site-packages/sqlalchemy/engine/default.py", line 736, in do_execute
    cursor.execute(statement, parameters)
psycopg2.errors.UndefinedTable: relation "ods_supplier" does not exist
LINE 1: SELECT COUNT(*) FROM ods_supplier
                             ^


The above exception was the direct cause of the following exception:

Traceback (most recent call last):
  File "/home/airflow/.local/lib/python3.8/site-packages/airflow/operators/python.py", line 192, in execute
    return_value = self.execute_callable()
  File "/home/airflow/.local/lib/python3.8/site-packages/airflow/operators/python.py", line 209, in execute_callable
    return self.python_callable(*self.op_args, **self.op_kwargs)
  File "/opt/airflow/walmart-etl/generate_synthetic_data.py", line 486, in main
    suppliers = generate_supplier_data(num_suppliers=50)
  File "/opt/airflow/walmart-etl/generate_synthetic_data.py", line 31, in generate_supplier_data
    result = conn.execute(text("SELECT COUNT(*) FROM ods_supplier"))
  File "/home/airflow/.local/lib/python3.8/site-packages/sqlalchemy/engine/base.py", line 1385, in execute
    return meth(self, multiparams, params, _EMPTY_EXECUTION_OPTS)
  File "/home/airflow/.local/lib/python3.8/site-packages/sqlalchemy/sql/elements.py", line 334, in _execute_on_connection
    return connection._execute_clauseelement(
  File "/home/airflow/.local/lib/python3.8/site-packages/sqlalchemy/engine/base.py", line 1577, in _execute_clauseelement
    ret = self._execute_context(
  File "/home/airflow/.local/lib/python3.8/site-packages/sqlalchemy/engine/base.py", line 1953, in _execute_context
    self._handle_dbapi_exception(
  File "/home/airflow/.local/lib/python3.8/site-packages/sqlalchemy/engine/base.py", line 2134, in _handle_dbapi_exception
    util.raise_(
  File "/home/airflow/.local/lib/python3.8/site-packages/sqlalchemy/util/compat.py", line 211, in raise_
    raise exception
  File "/home/airflow/.local/lib/python3.8/site-packages/sqlalchemy/engine/base.py", line 1910, in _execute_context
    self.dialect.do_execute(
  File "/home/airflow/.local/lib/python3.8/site-packages/sqlalchemy/engine/default.py", line 736, in do_execute
    cursor.execute(statement, parameters)
sqlalchemy.exc.ProgrammingError: (psycopg2.errors.UndefinedTable) relation "ods_supplier" does not exist
LINE 1: SELECT COUNT(*) FROM ods_supplier
                             ^

[SQL: SELECT COUNT(*) FROM ods_supplier]
(Background on this error at: https://sqlalche.me/e/14/f405)
[2025-05-27T05:17:58.137+0000] {taskinstance.py:1400} INFO - Marking task as UP_FOR_RETRY. dag_id=walmart_etl_dag, task_id=generate_synthetic_data, execution_date=20250527T051747, start_date=20250527T051757, end_date=20250527T051758
[2025-05-27T05:17:58.169+0000] {standard_task_runner.py:104} ERROR - Failed to execute job 25 for task generate_synthetic_data ((psycopg2.errors.UndefinedTable) relation "ods_supplier" does not exist
LINE 1: SELECT COUNT(*) FROM ods_supplier
                             ^

[SQL: SELECT COUNT(*) FROM ods_supplier]
(Background on this error at: https://sqlalche.me/e/14/f405); 89)
[2025-05-27T05:17:58.196+0000] {local_task_job_runner.py:228} INFO - Task exited with return code 1
[2025-05-27T05:17:58.225+0000] {taskinstance.py:2778} INFO - 0 downstream tasks scheduled from follow-on schedule check
