[2025-05-27T18:55:13.775+0000] {taskinstance.py:1159} INFO - Dependencies all met for dep_context=non-requeueable deps ti=<TaskInstance: walmart_etl_dag.load_to_target manual__2025-05-27T18:55:02+00:00 [queued]>
[2025-05-27T18:55:13.779+0000] {taskinstance.py:1159} INFO - Dependencies all met for dep_context=requeueable deps ti=<TaskInstance: walmart_etl_dag.load_to_target manual__2025-05-27T18:55:02+00:00 [queued]>
[2025-05-27T18:55:13.780+0000] {taskinstance.py:1361} INFO - Starting attempt 1 of 2
[2025-05-27T18:55:13.785+0000] {taskinstance.py:1382} INFO - Executing <Task(PythonOperator): load_to_target> on 2025-05-27 18:55:02+00:00
[2025-05-27T18:55:13.789+0000] {standard_task_runner.py:57} INFO - Started process 719 to run task
[2025-05-27T18:55:13.792+0000] {standard_task_runner.py:84} INFO - Running: ['***', 'tasks', 'run', 'walmart_etl_dag', 'load_to_target', 'manual__2025-05-27T18:55:02+00:00', '--job-id', '262', '--raw', '--subdir', 'DAGS_FOLDER/walmart_etl_dag.py', '--cfg-path', '/tmp/tmpznu9uze9']
[2025-05-27T18:55:13.794+0000] {standard_task_runner.py:85} INFO - Job 262: Subtask load_to_target
[2025-05-27T18:55:13.826+0000] {task_command.py:416} INFO - Running <TaskInstance: walmart_etl_dag.load_to_target manual__2025-05-27T18:55:02+00:00 [running]> on host d80f98a6628f
[2025-05-27T18:55:14.125+0000] {taskinstance.py:1662} INFO - Exporting env vars: AIRFLOW_CTX_DAG_OWNER='***' AIRFLOW_CTX_DAG_ID='walmart_etl_dag' AIRFLOW_CTX_TASK_ID='load_to_target' AIRFLOW_CTX_EXECUTION_DATE='2025-05-27T18:55:02+00:00' AIRFLOW_CTX_TRY_NUMBER='1' AIRFLOW_CTX_DAG_RUN_ID='manual__2025-05-27T18:55:02+00:00'
[2025-05-27T18:55:14.132+0000] {logging_mixin.py:154} INFO - Starting load to target layer for batch BATCH_20250527185510...
[2025-05-27T18:55:14.135+0000] {logging_mixin.py:154} INFO - Ensuring all required dates are in the date dimension...
[2025-05-27T18:55:14.138+0000] {taskinstance.py:1937} ERROR - Task failed with exception
Traceback (most recent call last):
  File "/home/airflow/.local/lib/python3.8/site-packages/sqlalchemy/engine/base.py", line 1910, in _execute_context
    self.dialect.do_execute(
  File "/home/airflow/.local/lib/python3.8/site-packages/sqlalchemy/engine/default.py", line 736, in do_execute
    cursor.execute(statement, parameters)
psycopg2.errors.UndefinedColumn: column "month_of_year" of relation "tgt_dim_date" does not exist
LINE 4:                             week_of_year, month_of_year, qua...
                                                  ^


The above exception was the direct cause of the following exception:

Traceback (most recent call last):
  File "/home/airflow/.local/lib/python3.8/site-packages/airflow/operators/python.py", line 192, in execute
    return_value = self.execute_callable()
  File "/home/airflow/.local/lib/python3.8/site-packages/airflow/operators/python.py", line 209, in execute_callable
    return self.python_callable(*self.op_args, **self.op_kwargs)
  File "/opt/airflow/dags/walmart_etl_dag.py", line 109, in etl_load_to_target
    load_to_target(engine, batch_id)
  File "/opt/airflow/walmart-etl/etl_data_loader.py", line 782, in load_to_target
    conn.execute(insert_query, {
  File "/home/airflow/.local/lib/python3.8/site-packages/sqlalchemy/engine/base.py", line 1385, in execute
    return meth(self, multiparams, params, _EMPTY_EXECUTION_OPTS)
  File "/home/airflow/.local/lib/python3.8/site-packages/sqlalchemy/sql/elements.py", line 334, in _execute_on_connection
    return connection._execute_clauseelement(
  File "/home/airflow/.local/lib/python3.8/site-packages/sqlalchemy/engine/base.py", line 1577, in _execute_clauseelement
    ret = self._execute_context(
  File "/home/airflow/.local/lib/python3.8/site-packages/sqlalchemy/engine/base.py", line 1953, in _execute_context
    self._handle_dbapi_exception(
  File "/home/airflow/.local/lib/python3.8/site-packages/sqlalchemy/engine/base.py", line 2134, in _handle_dbapi_exception
    util.raise_(
  File "/home/airflow/.local/lib/python3.8/site-packages/sqlalchemy/util/compat.py", line 211, in raise_
    raise exception
  File "/home/airflow/.local/lib/python3.8/site-packages/sqlalchemy/engine/base.py", line 1910, in _execute_context
    self.dialect.do_execute(
  File "/home/airflow/.local/lib/python3.8/site-packages/sqlalchemy/engine/default.py", line 736, in do_execute
    cursor.execute(statement, parameters)
sqlalchemy.exc.ProgrammingError: (psycopg2.errors.UndefinedColumn) column "month_of_year" of relation "tgt_dim_date" does not exist
LINE 4:                             week_of_year, month_of_year, qua...
                                                  ^

[SQL: 
                        INSERT INTO tgt_dim_date (
                            date_key, full_date, day_of_week, day_of_month, day_of_year,
                            week_of_year, month_of_year, quarter, year, is_weekend, is_holiday
                        ) VALUES (
                            %(date_key)s, %(full_date)s, %(day_of_week)s, %(day_of_month)s, %(day_of_year)s,
                            %(week_of_year)s, %(month_of_year)s, %(quarter)s, %(year)s, %(is_weekend)s, %(is_holiday)s
                        )
                    ]
[parameters: {'date_key': 20250227, 'full_date': datetime.date(2025, 2, 27), 'day_of_week': 4, 'day_of_month': 27, 'day_of_year': 58, 'week_of_year': 9, 'month_of_year': 2, 'quarter': 1, 'year': 2025, 'is_weekend': False, 'is_holiday': False}]
(Background on this error at: https://sqlalche.me/e/14/f405)
[2025-05-27T18:55:14.151+0000] {taskinstance.py:1400} INFO - Marking task as UP_FOR_RETRY. dag_id=walmart_etl_dag, task_id=load_to_target, execution_date=20250527T185502, start_date=20250527T185513, end_date=20250527T185514
[2025-05-27T18:55:14.157+0000] {standard_task_runner.py:104} ERROR - Failed to execute job 262 for task load_to_target ((psycopg2.errors.UndefinedColumn) column "month_of_year" of relation "tgt_dim_date" does not exist
LINE 4:                             week_of_year, month_of_year, qua...
                                                  ^

[SQL: 
                        INSERT INTO tgt_dim_date (
                            date_key, full_date, day_of_week, day_of_month, day_of_year,
                            week_of_year, month_of_year, quarter, year, is_weekend, is_holiday
                        ) VALUES (
                            %(date_key)s, %(full_date)s, %(day_of_week)s, %(day_of_month)s, %(day_of_year)s,
                            %(week_of_year)s, %(month_of_year)s, %(quarter)s, %(year)s, %(is_weekend)s, %(is_holiday)s
                        )
                    ]
[parameters: {'date_key': 20250227, 'full_date': datetime.date(2025, 2, 27), 'day_of_week': 4, 'day_of_month': 27, 'day_of_year': 58, 'week_of_year': 9, 'month_of_year': 2, 'quarter': 1, 'year': 2025, 'is_weekend': False, 'is_holiday': False}]
(Background on this error at: https://sqlalche.me/e/14/f405); 719)
[2025-05-27T18:55:14.194+0000] {local_task_job_runner.py:228} INFO - Task exited with return code 1
[2025-05-27T18:55:14.210+0000] {taskinstance.py:2778} INFO - 0 downstream tasks scheduled from follow-on schedule check
