[2025-05-27T18:53:40.668+0000] {taskinstance.py:1159} INFO - Dependencies all met for dep_context=non-requeueable deps ti=<TaskInstance: walmart_etl_dag.load_to_target manual__2025-05-27T18:43:16+00:00 [queued]>
[2025-05-27T18:53:40.673+0000] {taskinstance.py:1159} INFO - Dependencies all met for dep_context=requeueable deps ti=<TaskInstance: walmart_etl_dag.load_to_target manual__2025-05-27T18:43:16+00:00 [queued]>
[2025-05-27T18:53:40.673+0000] {taskinstance.py:1361} INFO - Starting attempt 2 of 2
[2025-05-27T18:53:40.679+0000] {taskinstance.py:1382} INFO - Executing <Task(PythonOperator): load_to_target> on 2025-05-27 18:43:16+00:00
[2025-05-27T18:53:40.683+0000] {standard_task_runner.py:57} INFO - Started process 680 to run task
[2025-05-27T18:53:40.685+0000] {standard_task_runner.py:84} INFO - Running: ['***', 'tasks', 'run', 'walmart_etl_dag', 'load_to_target', 'manual__2025-05-27T18:43:16+00:00', '--job-id', '257', '--raw', '--subdir', 'DAGS_FOLDER/walmart_etl_dag.py', '--cfg-path', '/tmp/tmpcgwu80mt']
[2025-05-27T18:53:40.688+0000] {standard_task_runner.py:85} INFO - Job 257: Subtask load_to_target
[2025-05-27T18:53:40.721+0000] {task_command.py:416} INFO - Running <TaskInstance: walmart_etl_dag.load_to_target manual__2025-05-27T18:43:16+00:00 [running]> on host d80f98a6628f
[2025-05-27T18:53:40.956+0000] {taskinstance.py:1662} INFO - Exporting env vars: AIRFLOW_CTX_DAG_OWNER='***' AIRFLOW_CTX_DAG_ID='walmart_etl_dag' AIRFLOW_CTX_TASK_ID='load_to_target' AIRFLOW_CTX_EXECUTION_DATE='2025-05-27T18:43:16+00:00' AIRFLOW_CTX_TRY_NUMBER='2' AIRFLOW_CTX_DAG_RUN_ID='manual__2025-05-27T18:43:16+00:00'
[2025-05-27T18:53:40.962+0000] {logging_mixin.py:154} INFO - Starting load to target layer for batch BATCH_20250527184823...
[2025-05-27T18:53:40.967+0000] {logging_mixin.py:154} INFO - Ensuring all required dates are in the date dimension...
[2025-05-27T18:53:40.974+0000] {taskinstance.py:1937} ERROR - Task failed with exception
Traceback (most recent call last):
  File "/home/airflow/.local/lib/python3.8/site-packages/airflow/operators/python.py", line 192, in execute
    return_value = self.execute_callable()
  File "/home/airflow/.local/lib/python3.8/site-packages/airflow/operators/python.py", line 209, in execute_callable
    return self.python_callable(*self.op_args, **self.op_kwargs)
  File "/opt/airflow/dags/walmart_etl_dag.py", line 109, in etl_load_to_target
    load_to_target(engine, batch_id)
  File "/opt/airflow/walmart-etl/etl_data_loader.py", line 769, in load_to_target
    date_obj = date(year, month, day)
NameError: name 'date' is not defined
[2025-05-27T18:53:40.985+0000] {taskinstance.py:1400} INFO - Marking task as FAILED. dag_id=walmart_etl_dag, task_id=load_to_target, execution_date=20250527T184316, start_date=20250527T185340, end_date=20250527T185340
[2025-05-27T18:53:40.993+0000] {standard_task_runner.py:104} ERROR - Failed to execute job 257 for task load_to_target (name 'date' is not defined; 680)
[2025-05-27T18:53:41.003+0000] {local_task_job_runner.py:228} INFO - Task exited with return code 1
[2025-05-27T18:53:41.023+0000] {taskinstance.py:2778} INFO - 0 downstream tasks scheduled from follow-on schedule check
