[2025-05-27T05:24:01.274+0000] {taskinstance.py:1159} INFO - Dependencies all met for dep_context=non-requeueable deps ti=<TaskInstance: walmart_etl_dag.load_to_ods manual__2025-05-27T05:23:58+00:00 [queued]>
[2025-05-27T05:24:01.282+0000] {taskinstance.py:1159} INFO - Dependencies all met for dep_context=requeueable deps ti=<TaskInstance: walmart_etl_dag.load_to_ods manual__2025-05-27T05:23:58+00:00 [queued]>
[2025-05-27T05:24:01.283+0000] {taskinstance.py:1361} INFO - Starting attempt 1 of 2
[2025-05-27T05:24:01.290+0000] {taskinstance.py:1382} INFO - Executing <Task(PythonOperator): load_to_ods> on 2025-05-27 05:23:58+00:00
[2025-05-27T05:24:01.295+0000] {standard_task_runner.py:57} INFO - Started process 94 to run task
[2025-05-27T05:24:01.297+0000] {standard_task_runner.py:84} INFO - Running: ['***', 'tasks', 'run', 'walmart_etl_dag', 'load_to_ods', 'manual__2025-05-27T05:23:58+00:00', '--job-id', '34', '--raw', '--subdir', 'DAGS_FOLDER/walmart_etl_dag.py', '--cfg-path', '/tmp/tmpc4mz5ifr']
[2025-05-27T05:24:01.298+0000] {standard_task_runner.py:85} INFO - Job 34: Subtask load_to_ods
[2025-05-27T05:24:01.322+0000] {task_command.py:416} INFO - Running <TaskInstance: walmart_etl_dag.load_to_ods manual__2025-05-27T05:23:58+00:00 [running]> on host 364c8c3dd6ab
[2025-05-27T05:24:01.354+0000] {taskinstance.py:1662} INFO - Exporting env vars: AIRFLOW_CTX_DAG_OWNER='***' AIRFLOW_CTX_DAG_ID='walmart_etl_dag' AIRFLOW_CTX_TASK_ID='load_to_ods' AIRFLOW_CTX_EXECUTION_DATE='2025-05-27T05:23:58+00:00' AIRFLOW_CTX_TRY_NUMBER='1' AIRFLOW_CTX_DAG_RUN_ID='manual__2025-05-27T05:23:58+00:00'
[2025-05-27T05:24:01.384+0000] {logging_mixin.py:154} INFO - Loaded 8399 rows from CSV file.
[2025-05-27T05:24:01.613+0000] {taskinstance.py:1937} ERROR - Task failed with exception
Traceback (most recent call last):
  File "/home/airflow/.local/lib/python3.8/site-packages/airflow/operators/python.py", line 192, in execute
    return_value = self.execute_callable()
  File "/home/airflow/.local/lib/python3.8/site-packages/airflow/operators/python.py", line 209, in execute_callable
    return self.python_callable(*self.op_args, **self.op_kwargs)
  File "/opt/airflow/dags/walmart_etl_dag.py", line 84, in etl_load_to_ods
    load_ods_layer(engine, df)
  File "/opt/airflow/walmart-etl/etl_data_loader.py", line 338, in load_ods_layer
    load_ods_date_dimension(engine, df)
  File "/opt/airflow/walmart-etl/etl_data_loader.py", line 110, in load_ods_date_dimension
    conn.commit()
AttributeError: 'Connection' object has no attribute 'commit'
[2025-05-27T05:24:01.620+0000] {taskinstance.py:1400} INFO - Marking task as UP_FOR_RETRY. dag_id=walmart_etl_dag, task_id=load_to_ods, execution_date=20250527T052358, start_date=20250527T052401, end_date=20250527T052401
[2025-05-27T05:24:01.627+0000] {standard_task_runner.py:104} ERROR - Failed to execute job 34 for task load_to_ods ('Connection' object has no attribute 'commit'; 94)
[2025-05-27T05:24:01.650+0000] {local_task_job_runner.py:228} INFO - Task exited with return code 1
[2025-05-27T05:24:01.665+0000] {taskinstance.py:2778} INFO - 0 downstream tasks scheduled from follow-on schedule check
